WARNING [2018-08-07 22:13:30] [None]  Heeh! Error occured while getting a DB profile for 'None':
	b'NOT NULL constraint failed: profiles.name'
ERROR [2018-08-07 22:13:30] [None]  Message: 'chromedriver' executable needs to be in PATH. Please see https://sites.google.com/a/chromium.org/chromedriver/home
Traceback (most recent call last):
  File "/Users/GabeSpags/venv/lib/python3.7/site-packages/selenium/webdriver/common/service.py", line 64, in start
    stdout=self.log_file, stderr=self.log_file)
  File "/Library/Frameworks/Python.framework/Versions/3.7/lib/python3.7/subprocess.py", line 756, in __init__
    restore_signals, start_new_session)
  File "/Library/Frameworks/Python.framework/Versions/3.7/lib/python3.7/subprocess.py", line 1499, in _execute_child
    raise child_exception_type(errno_num, err_msg, err_filename)
FileNotFoundError: [Errno 2] No such file or directory: '/Users/GabeSpags/venv/InstaPy/assets/chromedriver': '/Users/GabeSpags/venv/InstaPy/assets/chromedriver'

During handling of the above exception, another exception occurred:

Traceback (most recent call last):
  File "/Users/GabeSpags/venv/InstaPy/instapy/instapy.py", line 300, in set_selenium_local_session
    chrome_options=chrome_options)
  File "/Users/GabeSpags/venv/lib/python3.7/site-packages/selenium/webdriver/chrome/webdriver.py", line 62, in __init__
    self.service.start()
  File "/Users/GabeSpags/venv/lib/python3.7/site-packages/selenium/webdriver/common/service.py", line 71, in start
    os.path.basename(self.path), self.start_error_message)
selenium.common.exceptions.WebDriverException: Message: 'chromedriver' executable needs to be in PATH. Please see https://sites.google.com/a/chromium.org/chromedriver/home

WARNING [2018-08-07 22:15:45] [None]  Heeh! Error occured while getting a DB profile for 'None':
	b'NOT NULL constraint failed: profiles.name'
ERROR [2018-08-07 22:15:45] [None]  Message: 'chromedriver' executable needs to be in PATH. Please see https://sites.google.com/a/chromium.org/chromedriver/home
Traceback (most recent call last):
  File "/Users/GabeSpags/venv/lib/python3.7/site-packages/selenium/webdriver/common/service.py", line 64, in start
    stdout=self.log_file, stderr=self.log_file)
  File "/Library/Frameworks/Python.framework/Versions/3.7/lib/python3.7/subprocess.py", line 756, in __init__
    restore_signals, start_new_session)
  File "/Library/Frameworks/Python.framework/Versions/3.7/lib/python3.7/subprocess.py", line 1499, in _execute_child
    raise child_exception_type(errno_num, err_msg, err_filename)
FileNotFoundError: [Errno 2] No such file or directory: '/Users/GabeSpags/venv/InstaPy/assets/chromedriver': '/Users/GabeSpags/venv/InstaPy/assets/chromedriver'

During handling of the above exception, another exception occurred:

Traceback (most recent call last):
  File "/Users/GabeSpags/venv/InstaPy/instapy/instapy.py", line 300, in set_selenium_local_session
    chrome_options=chrome_options)
  File "/Users/GabeSpags/venv/lib/python3.7/site-packages/selenium/webdriver/chrome/webdriver.py", line 62, in __init__
    self.service.start()
  File "/Users/GabeSpags/venv/lib/python3.7/site-packages/selenium/webdriver/common/service.py", line 71, in start
    os.path.basename(self.path), self.start_error_message)
selenium.common.exceptions.WebDriverException: Message: 'chromedriver' executable needs to be in PATH. Please see https://sites.google.com/a/chromium.org/chromedriver/home

WARNING [2018-08-07 22:15:51] [None]  Heeh! Error occured while getting a DB profile for 'None':
	b'NOT NULL constraint failed: profiles.name'
ERROR [2018-08-07 22:15:51] [None]  Message: 'chromedriver' executable needs to be in PATH. Please see https://sites.google.com/a/chromium.org/chromedriver/home
Traceback (most recent call last):
  File "/Users/GabeSpags/venv/lib/python3.7/site-packages/selenium/webdriver/common/service.py", line 64, in start
    stdout=self.log_file, stderr=self.log_file)
  File "/Library/Frameworks/Python.framework/Versions/3.7/lib/python3.7/subprocess.py", line 756, in __init__
    restore_signals, start_new_session)
  File "/Library/Frameworks/Python.framework/Versions/3.7/lib/python3.7/subprocess.py", line 1499, in _execute_child
    raise child_exception_type(errno_num, err_msg, err_filename)
FileNotFoundError: [Errno 2] No such file or directory: '/Users/GabeSpags/venv/InstaPy/assets/chromedriver': '/Users/GabeSpags/venv/InstaPy/assets/chromedriver'

During handling of the above exception, another exception occurred:

Traceback (most recent call last):
  File "/Users/GabeSpags/venv/InstaPy/instapy/instapy.py", line 300, in set_selenium_local_session
    chrome_options=chrome_options)
  File "/Users/GabeSpags/venv/lib/python3.7/site-packages/selenium/webdriver/chrome/webdriver.py", line 62, in __init__
    self.service.start()
  File "/Users/GabeSpags/venv/lib/python3.7/site-packages/selenium/webdriver/common/service.py", line 71, in start
    os.path.basename(self.path), self.start_error_message)
selenium.common.exceptions.WebDriverException: Message: 'chromedriver' executable needs to be in PATH. Please see https://sites.google.com/a/chromium.org/chromedriver/home

WARNING [2018-08-07 22:15:54] [None]  Heeh! Error occured while getting a DB profile for 'None':
	b'NOT NULL constraint failed: profiles.name'
ERROR [2018-08-07 22:15:54] [None]  Message: 'chromedriver' executable needs to be in PATH. Please see https://sites.google.com/a/chromium.org/chromedriver/home
Traceback (most recent call last):
  File "/Users/GabeSpags/venv/lib/python3.7/site-packages/selenium/webdriver/common/service.py", line 64, in start
    stdout=self.log_file, stderr=self.log_file)
  File "/Library/Frameworks/Python.framework/Versions/3.7/lib/python3.7/subprocess.py", line 756, in __init__
    restore_signals, start_new_session)
  File "/Library/Frameworks/Python.framework/Versions/3.7/lib/python3.7/subprocess.py", line 1499, in _execute_child
    raise child_exception_type(errno_num, err_msg, err_filename)
FileNotFoundError: [Errno 2] No such file or directory: '/Users/GabeSpags/venv/InstaPy/assets/chromedriver': '/Users/GabeSpags/venv/InstaPy/assets/chromedriver'

During handling of the above exception, another exception occurred:

Traceback (most recent call last):
  File "/Users/GabeSpags/venv/InstaPy/instapy/instapy.py", line 300, in set_selenium_local_session
    chrome_options=chrome_options)
  File "/Users/GabeSpags/venv/lib/python3.7/site-packages/selenium/webdriver/chrome/webdriver.py", line 62, in __init__
    self.service.start()
  File "/Users/GabeSpags/venv/lib/python3.7/site-packages/selenium/webdriver/common/service.py", line 71, in start
    os.path.basename(self.path), self.start_error_message)
selenium.common.exceptions.WebDriverException: Message: 'chromedriver' executable needs to be in PATH. Please see https://sites.google.com/a/chromium.org/chromedriver/home

WARNING [2018-08-07 22:15:58] [None]  Heeh! Error occured while getting a DB profile for 'None':
	b'NOT NULL constraint failed: profiles.name'
ERROR [2018-08-07 22:15:58] [None]  Message: 'chromedriver' executable needs to be in PATH. Please see https://sites.google.com/a/chromium.org/chromedriver/home
Traceback (most recent call last):
  File "/Users/GabeSpags/venv/lib/python3.7/site-packages/selenium/webdriver/common/service.py", line 64, in start
    stdout=self.log_file, stderr=self.log_file)
  File "/Library/Frameworks/Python.framework/Versions/3.7/lib/python3.7/subprocess.py", line 756, in __init__
    restore_signals, start_new_session)
  File "/Library/Frameworks/Python.framework/Versions/3.7/lib/python3.7/subprocess.py", line 1499, in _execute_child
    raise child_exception_type(errno_num, err_msg, err_filename)
FileNotFoundError: [Errno 2] No such file or directory: '/Users/GabeSpags/venv/InstaPy/assets/chromedriver': '/Users/GabeSpags/venv/InstaPy/assets/chromedriver'

During handling of the above exception, another exception occurred:

Traceback (most recent call last):
  File "/Users/GabeSpags/venv/InstaPy/instapy/instapy.py", line 300, in set_selenium_local_session
    chrome_options=chrome_options)
  File "/Users/GabeSpags/venv/lib/python3.7/site-packages/selenium/webdriver/chrome/webdriver.py", line 62, in __init__
    self.service.start()
  File "/Users/GabeSpags/venv/lib/python3.7/site-packages/selenium/webdriver/common/service.py", line 71, in start
    os.path.basename(self.path), self.start_error_message)
selenium.common.exceptions.WebDriverException: Message: 'chromedriver' executable needs to be in PATH. Please see https://sites.google.com/a/chromium.org/chromedriver/home

WARNING [2018-08-07 22:16:01] [None]  Heeh! Error occured while getting a DB profile for 'None':
	b'NOT NULL constraint failed: profiles.name'
ERROR [2018-08-07 22:16:01] [None]  Message: 'chromedriver' executable needs to be in PATH. Please see https://sites.google.com/a/chromium.org/chromedriver/home
Traceback (most recent call last):
  File "/Users/GabeSpags/venv/lib/python3.7/site-packages/selenium/webdriver/common/service.py", line 64, in start
    stdout=self.log_file, stderr=self.log_file)
  File "/Library/Frameworks/Python.framework/Versions/3.7/lib/python3.7/subprocess.py", line 756, in __init__
    restore_signals, start_new_session)
  File "/Library/Frameworks/Python.framework/Versions/3.7/lib/python3.7/subprocess.py", line 1499, in _execute_child
    raise child_exception_type(errno_num, err_msg, err_filename)
FileNotFoundError: [Errno 2] No such file or directory: '/Users/GabeSpags/venv/InstaPy/assets/chromedriver': '/Users/GabeSpags/venv/InstaPy/assets/chromedriver'

During handling of the above exception, another exception occurred:

Traceback (most recent call last):
  File "/Users/GabeSpags/venv/InstaPy/instapy/instapy.py", line 300, in set_selenium_local_session
    chrome_options=chrome_options)
  File "/Users/GabeSpags/venv/lib/python3.7/site-packages/selenium/webdriver/chrome/webdriver.py", line 62, in __init__
    self.service.start()
  File "/Users/GabeSpags/venv/lib/python3.7/site-packages/selenium/webdriver/common/service.py", line 71, in start
    os.path.basename(self.path), self.start_error_message)
selenium.common.exceptions.WebDriverException: Message: 'chromedriver' executable needs to be in PATH. Please see https://sites.google.com/a/chromium.org/chromedriver/home

WARNING [2018-08-07 22:16:06] [None]  Heeh! Error occured while getting a DB profile for 'None':
	b'NOT NULL constraint failed: profiles.name'
ERROR [2018-08-07 22:16:06] [None]  Message: 'chromedriver' executable needs to be in PATH. Please see https://sites.google.com/a/chromium.org/chromedriver/home
Traceback (most recent call last):
  File "/Users/GabeSpags/venv/lib/python3.7/site-packages/selenium/webdriver/common/service.py", line 64, in start
    stdout=self.log_file, stderr=self.log_file)
  File "/Library/Frameworks/Python.framework/Versions/3.7/lib/python3.7/subprocess.py", line 756, in __init__
    restore_signals, start_new_session)
  File "/Library/Frameworks/Python.framework/Versions/3.7/lib/python3.7/subprocess.py", line 1499, in _execute_child
    raise child_exception_type(errno_num, err_msg, err_filename)
FileNotFoundError: [Errno 2] No such file or directory: '/Users/GabeSpags/venv/InstaPy/assets/chromedriver': '/Users/GabeSpags/venv/InstaPy/assets/chromedriver'

During handling of the above exception, another exception occurred:

Traceback (most recent call last):
  File "/Users/GabeSpags/venv/InstaPy/instapy/instapy.py", line 300, in set_selenium_local_session
    chrome_options=chrome_options)
  File "/Users/GabeSpags/venv/lib/python3.7/site-packages/selenium/webdriver/chrome/webdriver.py", line 62, in __init__
    self.service.start()
  File "/Users/GabeSpags/venv/lib/python3.7/site-packages/selenium/webdriver/common/service.py", line 71, in start
    os.path.basename(self.path), self.start_error_message)
selenium.common.exceptions.WebDriverException: Message: 'chromedriver' executable needs to be in PATH. Please see https://sites.google.com/a/chromium.org/chromedriver/home

